Workbook

Sheet Summary
A1: Supplementary File 2: Lesion sizes of patients who failed conventional therapies.
A2: Patient | B2: N1 | C2: N2 | D2: N3 | E2: N4 | F2: N5 | G2: N6 | H2: N7 | I2: N8 | J2: N9 | K2: N10 | L2: N11 | M2: N12 | N2: N13 | O2: N14 | P2: N15 | Q2: N16 | R2: N17 | S2: N18 | T2: N19 | U2: N20 | V2: N21 | W2: N22
A3: Met. 1 | B3: =OFFSET(Volume!B3,3-ROW(),ROW()-3)*10^9 -> 222912000000 | C3: =OFFSET(Volume!C3,4-ROW(),ROW()-4)*10^9 -> 137499500000 | D3: =OFFSET(Volume!D3,5-ROW(),ROW()-5)*10^9 -> 46227500000 | E3: =OFFSET(Volume!E3,6-ROW(),ROW()-6)*10^9 -> 49818000000 | F3: =OFFSET(Volume!F3,7-ROW(),ROW()-7)*10^9 -> 46746000000 | G3: =OFFSET(Volume!G3,8-ROW(),ROW()-8)*10^9 -> 77247500000 | H3: =OFFSET(Volume!H3,9-ROW(),ROW()-9)*10^9 -> 24500000000 | I3: =OFFSET(Volume!I3,10-ROW(),ROW()-10)*10^9 -> 48998500000 | J3: =OFFSET(Volume!J3,11-ROW(),ROW()-11)*10^9 -> 47587500000 | K3: =OFFSET(Volume!K3,12-ROW(),ROW()-12)*10^9 -> 26568000000 | L3: =OFFSET(Volume!L3,13-ROW(),ROW()-13)*10^9 -> 36822000000 | M3: =OFFSET(Volume!M3,14-ROW(),ROW()-14)*10^9 -> 20992000000 | N3: =OFFSET(Volume!N3,15-ROW(),ROW()-15)*10^9 -> 10478000000 | O3: =OFFSET(Volume!O3,16-ROW(),ROW()-16)*10^9 -> 26491500000 | P3: =OFFSET(Volume!P3,17-ROW(),ROW()-17)*10^9 -> 25047000000 | Q3: =OFFSET(Volume!Q3,18-ROW(),ROW()-18)*10^9 -> 1.71e+10 | R3: =OFFSET(Volume!R3,19-ROW(),ROW()-19)*10^9 -> 10570500000 | S3: =OFFSET(Volume!S3,20-ROW(),ROW()-20)*10^9 -> 18954000000 | T3: =OFFSET(Volume!T3,21-ROW(),ROW()-21)*10^9 -> 15979000000 | U3: =OFFSET(Volume!U3,21-ROW(),ROW()-21)*10^9 -> 847000000 | V3: =OFFSET(Volume!V3,23-ROW(),ROW()-23)*10^9 -> 786500000 | W3: =OFFSET(Volume!W3,24-ROW(),ROW()-24)*10^9 -> 847000000
A4: Met. 2 | B4: =OFFSET(Volume!B4,3-ROW(),ROW()-3)*10^9 -> 13876500000 | C4: =OFFSET(Volume!C4,4-ROW(),ROW()-4)*10^9 -> 22869000000 | D4: =OFFSET(Volume!D4,5-ROW(),ROW()-5)*10^9 -> 30802500000 | E4: =OFFSET(Volume!E4,6-ROW(),ROW()-6)*10^9 -> 24276000000 | F4: =OFFSET(Volume!F4,7-ROW(),ROW()-7)*10^9 -> 19208000000 | G4: =OFFSET(Volume!G4,8-ROW(),ROW()-8)*10^9 -> 8064000000 | H4: =OFFSET(Volume!H4,9-ROW(),ROW()-9)*10^9 -> 22324500000 | I4: =OFFSET(Volume!I4,10-ROW(),ROW()-10)*10^9 -> 10816000000 | J4: =OFFSET(Volume!J4,11-ROW(),ROW()-11)*10^9 -> 12936000000 | K4: =OFFSET(Volume!K4,12-ROW(),ROW()-12)*10^9 -> 16072000000 | L4: =OFFSET(Volume!L4,13-ROW(),ROW()-13)*10^9 -> 4698000000 | M4: =OFFSET(Volume!M4,14-ROW(),ROW()-14)*10^9 -> 8125000000 | N4: =OFFSET(Volume!N4,15-ROW(),ROW()-15)*10^9 -> 8064000000 | O4: =OFFSET(Volume!O4,16-ROW(),ROW()-16)*10^9 -> 2842000000 | P4: =OFFSET(Volume!P4,17-ROW(),ROW()-17)*10^9 -> 2160000000 | Q4: =OFFSET(Volume!Q4,18-ROW(),ROW()-18)*10^9 -> 2745500000 | R4: =OFFSET(Volume!R4,19-ROW(),ROW()-19)*10^9 -> 2601000000 | S4: =OFFSET(Volume!S4,20-ROW(),ROW()-20)*10^9 -> 550000000 | T4: =OFFSET(Volume!T4,21-ROW(),ROW()-21)*10^9 -> 847000000 | U4: =OFFSET(Volume!U4,21-ROW(),ROW()-21)*10^9 -> 245000000 | V4: =OFFSET(Volume!V4,23-ROW(),ROW()-23)*10^9 -> 75000000
A5: Met. 3 | B5: =OFFSET(Volume!B5,3-ROW(),ROW()-3)*10^9 -> 6776000000 | C5: =OFFSET(Volume!C5,4-ROW(),ROW()-4)*10^9 -> 11760000000 | D5: =OFFSET(Volume!D5,5-ROW(),ROW()-5)*10^9 -> 20480000000 | E5: =OFFSET(Volume!E5,6-ROW(),ROW()-6)*10^9 -> 12152000000 | F5: =OFFSET(Volume!F5,7-ROW(),ROW()-7)*10^9 -> 12615000000 | G5: =OFFSET(Volume!G5,8-ROW(),ROW()-8)*10^9 -> 6200000000 | H5: =OFFSET(Volume!H5,9-ROW(),ROW()-9)*10^9 -> 19800000000 | I5: =OFFSET(Volume!I5,10-ROW(),ROW()-10)*10^9 -> 5733000000 | J5: =OFFSET(Volume!J5,11-ROW(),ROW()-11)*10^9 -> 936000000 | K5: =OFFSET(Volume!K5,12-ROW(),ROW()-12)*10^9 -> 9040500000 | L5: =OFFSET(Volume!L5,13-ROW(),ROW()-13)*10^9 -> 2456500000 | M5: =OFFSET(Volume!M5,14-ROW(),ROW()-14)*10^9 -> 7670500000 | N5: =OFFSET(Volume!N5,15-ROW(),ROW()-15)*10^9 -> 6615000000 | O5: =OFFSET(Volume!O5,16-ROW(),ROW()-16)*10^9 -> 1774500000 | P5: =OFFSET(Volume!P5,17-ROW(),ROW()-17)*10^9 -> 1512500000 | Q5: =OFFSET(Volume!Q5,18-ROW(),ROW()-18)*10^9 -> 1224000000 | R5: =OFFSET(Volume!R5,19-ROW(),ROW()-19)*10^9 -> 1470000000 | S5: =OFFSET(Volume!S5,20-ROW(),ROW()-20)*10^9 -> 320000000 | T5: =OFFSET(Volume!T5,21-ROW(),ROW()-21)*10^9 -> 245000000 | U5: =OFFSET(Volume!U5,21-ROW(),ROW()-21)*10^9 -> 198000000 | V5: =OFFSET(Volume!V5,23-ROW(),ROW()-23)*10^9 -> 75000000
A6: Met. 4 | B6: =OFFSET(Volume!B6,3-ROW(),ROW()-3)*10^9 -> 4050000000 | C6: =OFFSET(Volume!C6,4-ROW(),ROW()-4)*10^9 -> 9792000000 | D6: =OFFSET(Volume!D6,5-ROW(),ROW()-5)*10^9 -> 18000000000 | E6: =OFFSET(Volume!E6,6-ROW(),ROW()-6)*10^9 -> 9922000000 | F6: =OFFSET(Volume!F6,7-ROW(),ROW()-7)*10^9 -> 5324000000 | G6: =OFFSET(Volume!G6,8-ROW(),ROW()-8)*10^9 -> 2745500000 | H6: =OFFSET(Volume!H6,9-ROW(),ROW()-9)*10^9 -> 8954000000 | I6: =OFFSET(Volume!I6,10-ROW(),ROW()-10)*10^9 -> 3790500000 | J6: =OFFSET(Volume!J6,11-ROW(),ROW()-11)*10^9 -> 550000000 | K6: =OFFSET(Volume!K6,12-ROW(),ROW()-12)*10^9 -> 2475000000 | L6: =OFFSET(Volume!L6,13-ROW(),ROW()-13)*10^9 -> 2025000000 | M6: =OFFSET(Volume!M6,14-ROW(),ROW()-14)*10^9 -> 2890000000 | N6: =OFFSET(Volume!N6,15-ROW(),ROW()-15)*10^9 -> 5071500000 | O6: =OFFSET(Volume!O6,16-ROW(),ROW()-16)*10^9 -> 1372000000 | P6: =OFFSET(Volume!P6,17-ROW(),ROW()-17)*10^9 -> 1512000000 | Q6: =OFFSET(Volume!Q6,18-ROW(),ROW()-18)*10^9 -> 384000000 | R6: =OFFSET(Volume!R6,19-ROW(),ROW()-19)*10^9 -> 1267500000 | S6: =OFFSET(Volume!S6,20-ROW(),ROW()-20)*10^9 -> 256000000 | T6: =OFFSET(Volume!T6,21-ROW(),ROW()-21)*10^9 -> 198000000 | V6: =OFFSET(Volume!V6,23-ROW(),ROW()-23)*10^9 -> 40000000
A7: Met. 5 | B7: =OFFSET(Volume!B7,3-ROW(),ROW()-3)*10^9 -> 1862000000 | C7: =OFFSET(Volume!C7,4-ROW(),ROW()-4)*10^9 -> 9687500000 | D7: =OFFSET(Volume!D7,5-ROW(),ROW()-5)*10^9 -> 17661000000 | E7: =OFFSET(Volume!E7,6-ROW(),ROW()-6)*10^9 -> 4860000000 | F7: =OFFSET(Volume!F7,7-ROW(),ROW()-7)*10^9 -> 4800000000 | G7: =OFFSET(Volume!G7,8-ROW(),ROW()-8)*10^9 -> 1800000000 | H7: =OFFSET(Volume!H7,9-ROW(),ROW()-9)*10^9 -> 3072000000 | I7: =OFFSET(Volume!I7,10-ROW(),ROW()-10)*10^9 -> 2304000000 | J7: =OFFSET(Volume!J7,11-ROW(),ROW()-11)*10^9 -> 448000000 | K7: =OFFSET(Volume!K7,12-ROW(),ROW()-12)*10^9 -> 1000000000 | L7: =OFFSET(Volume!L7,13-ROW(),ROW()-13)*10^9 -> 1912500000 | M7: =OFFSET(Volume!M7,14-ROW(),ROW()-14)*10^9 -> 2176000000 | N7: =OFFSET(Volume!N7,15-ROW(),ROW()-15)*10^9 -> 3584000000 | O7: =OFFSET(Volume!O7,16-ROW(),ROW()-16)*10^9 -> 1331000000 | P7: =OFFSET(Volume!P7,17-ROW(),ROW()-17)*10^9 -> 1270500000 | Q7: =OFFSET(Volume!Q7,18-ROW(),ROW()-18)*10^9 -> 256000000 | R7: =OFFSET(Volume!R7,19-ROW(),ROW()-19)*10^9 -> 1183000000 | T7: =OFFSET(Volume!T7,21-ROW(),ROW()-21)*10^9 -> 180000000 | V7: =OFFSET(Volume!V7,23-ROW(),ROW()-23)*10^9 -> 40000000
A8: Met. 6 | B8: =OFFSET(Volume!B8,3-ROW(),ROW()-3)*10^9 -> 1224000000 | C8: =OFFSET(Volume!C8,4-ROW(),ROW()-4)*10^9 -> 7502000000 | D8: =OFFSET(Volume!D8,5-ROW(),ROW()-5)*10^9 -> 9802000000 | E8: =OFFSET(Volume!E8,6-ROW(),ROW()-6)*10^9 -> 3901500000 | F8: =OFFSET(Volume!F8,7-ROW(),ROW()-7)*10^9 -> 4.212e+09 | G8: =OFFSET(Volume!G8,8-ROW(),ROW()-8)*10^9 -> 1372000000 | H8: =OFFSET(Volume!H8,9-ROW(),ROW()-9)*10^9 -> 2925000000 | I8: =OFFSET(Volume!I8,10-ROW(),ROW()-10)*10^9 -> 1267500000 | J8: =OFFSET(Volume!J8,11-ROW(),ROW()-11)*10^9 -> 196000000 | L8: =OFFSET(Volume!L8,13-ROW(),ROW()-13)*10^9 -> 1687500000 | M8: =OFFSET(Volume!M8,14-ROW(),ROW()-14)*10^9 -> 1470000000 | N8: =OFFSET(Volume!N8,15-ROW(),ROW()-15)*10^9 -> 3328000000 | O8: =OFFSET(Volume!O8,16-ROW(),ROW()-16)*10^9 -> 1200000000 | P8: =OFFSET(Volume!P8,17-ROW(),ROW()-17)*10^9 -> 1152000000 | Q8: =OFFSET(Volume!Q8,18-ROW(),ROW()-18)*10^9 -> 144000000 | R8: =OFFSET(Volume!R8,19-ROW(),ROW()-19)*10^9 -> 1080000000 | T8: =OFFSET(Volume!T8,21-ROW(),ROW()-21)*10^9 -> 144000000 | V8: =OFFSET(Volume!V8,23-ROW(),ROW()-23)*10^9 -> 40000000
A9: Met. 7 | B9: =OFFSET(Volume!B9,3-ROW(),ROW()-3)*10^9 -> 750000000 | C9: =OFFSET(Volume!C9,4-ROW(),ROW()-4)*10^9 -> 6877000000 | D9: =OFFSET(Volume!D9,5-ROW(),ROW()-5)*10^9 -> 7141500000 | E9: =OFFSET(Volume!E9,6-ROW(),ROW()-6)*10^9 -> 3564000000 | F9: =OFFSET(Volume!F9,7-ROW(),ROW()-7)*10^9 -> 3034500000 | G9: =OFFSET(Volume!G9,8-ROW(),ROW()-8)*10^9 -> 500000000 | H9: =OFFSET(Volume!H9,9-ROW(),ROW()-9)*10^9 -> 1666000000 | I9: =OFFSET(Volume!I9,10-ROW(),ROW()-10)*10^9 -> 445500000 | J9: =OFFSET(Volume!J9,11-ROW(),ROW()-11)*10^9 -> 180000000 | L9: =OFFSET(Volume!L9,13-ROW(),ROW()-13)*10^9 -> 1267500000 | M9: =OFFSET(Volume!M9,14-ROW(),ROW()-14)*10^9 -> 1440000000 | N9: =OFFSET(Volume!N9,15-ROW(),ROW()-15)*10^9 -> 2688000000 | O9: =OFFSET(Volume!O9,16-ROW(),ROW()-16)*10^9 -> 1183000000 | P9: =OFFSET(Volume!P9,17-ROW(),ROW()-17)*10^9 -> 786500000 | Q9: =OFFSET(Volume!Q9,18-ROW(),ROW()-18)*10^9 -> 87500000 | R9: =OFFSET(Volume!R9,19-ROW(),ROW()-19)*10^9 -> 1008000000 | T9: =OFFSET(Volume!T9,21-ROW(),ROW()-21)*10^9 -> 144000000 | V9: =OFFSET(Volume!V9,23-ROW(),ROW()-23)*10^9 -> 32000000
A10: Met. 8 | B10: =OFFSET(Volume!B10,3-ROW(),ROW()-3)*10^9 -> 550000000 | C10: =OFFSET(Volume!C10,4-ROW(),ROW()-4)*10^9 -> 6534000000 | D10: =OFFSET(Volume!D10,5-ROW(),ROW()-5)*10^9 -> 3712000000 | E10: =OFFSET(Volume!E10,6-ROW(),ROW()-6)*10^9 -> 2944000000 | F10: =OFFSET(Volume!F10,7-ROW(),ROW()-7)*10^9 -> 2688000000 | G10: =OFFSET(Volume!G10,8-ROW(),ROW()-8)*10^9 -> 144000000 | H10: =OFFSET(Volume!H10,9-ROW(),ROW()-9)*10^9 -> 1352000000 | I10: =OFFSET(Volume!I10,10-ROW(),ROW()-10)*10^9 -> 256000000 | J10: =OFFSET(Volume!J10,11-ROW(),ROW()-11)*10^9 -> 171500000 | L10: =OFFSET(Volume!L10,13-ROW(),ROW()-13)*10^9 -> 1080000000 | M10: =OFFSET(Volume!M10,14-ROW(),ROW()-14)*10^9 -> 607500000 | N10: =OFFSET(Volume!N10,15-ROW(),ROW()-15)*10^9 -> 936000000 | O10: =OFFSET(Volume!O10,16-ROW(),ROW()-16)*10^9 -> 1098500000 | P10: =OFFSET(Volume!P10,17-ROW(),ROW()-17)*10^9 -> 648000000 | R10: =OFFSET(Volume!R10,19-ROW(),ROW()-19)*10^9 -> 847000000 | T10: =OFFSET(Volume!T10,21-ROW(),ROW()-21)*10^9 -> 126000000 | V10: =OFFSET(Volume!V10,23-ROW(),ROW()-23)*10^9 -> 32000000
A11: Met. 9 | B11: =OFFSET(Volume!B11,3-ROW(),ROW()-3)*10^9 -> 544000000 | C11: =OFFSET(Volume!C11,4-ROW(),ROW()-4)*10^9 -> 3610000000 | D11: =OFFSET(Volume!D11,5-ROW(),ROW()-5)*10^9 -> 3072000000 | E11: =OFFSET(Volume!E11,6-ROW(),ROW()-6)*10^9 -> 2944000000 | F11: =OFFSET(Volume!F11,7-ROW(),ROW()-7)*10^9 -> 1267500000 | H11: =OFFSET(Volume!H11,9-ROW(),ROW()-9)*10^9 -> 1149500000 | J11: =OFFSET(Volume!J11,11-ROW(),ROW()-11)*10^9 -> 126000000 | L11: =OFFSET(Volume!L11,13-ROW(),ROW()-13)*10^9 -> 750000000 | M11: =OFFSET(Volume!M11,14-ROW(),ROW()-14)*10^9 -> 550000000 | N11: =OFFSET(Volume!N11,15-ROW(),ROW()-15)*10^9 -> 288000000 | O11: =OFFSET(Volume!O11,16-ROW(),ROW()-16)*10^9 -> 1098500000 | R11: =OFFSET(Volume!R11,19-ROW(),ROW()-19)*10^9 -> 445500000 | T11: =OFFSET(Volume!T11,21-ROW(),ROW()-21)*10^9 -> 48000000 | V11: =OFFSET(Volume!V11,23-ROW(),ROW()-23)*10^9 -> 32000000
A12: Met. 10 | B12: =OFFSET(Volume!B12,3-ROW(),ROW()-3)*10^9 -> 486000000 | C12: =OFFSET(Volume!C12,4-ROW(),ROW()-4)*10^9 -> 3564000000 | D12: =OFFSET(Volume!D12,5-ROW(),ROW()-5)*10^9 -> 2890000000 | E12: =OFFSET(Volume!E12,6-ROW(),ROW()-6)*10^9 -> 2916000000 | F12: =OFFSET(Volume!F12,7-ROW(),ROW()-7)*10^9 -> 1008000000 | H12: =OFFSET(Volume!H12,9-ROW(),ROW()-9)*10^9 -> 1008000000 | J12: =OFFSET(Volume!J12,11-ROW(),ROW()-11)*10^9 -> 126000000 | L12: =OFFSET(Volume!L12,13-ROW(),ROW()-13)*10^9 -> 352000000 | M12: =OFFSET(Volume!M12,14-ROW(),ROW()-14)*10^9 -> 550000000 | O12: =OFFSET(Volume!O12,16-ROW(),ROW()-16)*10^9 -> 729000000 | R12: =OFFSET(Volume!R12,19-ROW(),ROW()-19)*10^9 -> 352000000 | V12: =OFFSET(Volume!V12,23-ROW(),ROW()-23)*10^9 -> 18000000
A13: Met. 11 | B13: =OFFSET(Volume!B13,3-ROW(),ROW()-3)*10^9 -> 405000000 | C13: =OFFSET(Volume!C13,4-ROW(),ROW()-4)*10^9 -> 3034500000 | D13: =OFFSET(Volume!D13,5-ROW(),ROW()-5)*10^9 -> 2456500000 | E13: =OFFSET(Volume!E13,6-ROW(),ROW()-6)*10^9 -> 2816000000 | F13: =OFFSET(Volume!F13,7-ROW(),ROW()-7)*10^9 -> 729000000 | H13: =OFFSET(Volume!H13,9-ROW(),ROW()-9)*10^9 -> 650000000 | J13: =OFFSET(Volume!J13,11-ROW(),ROW()-11)*10^9 -> 108000000 | L13: =OFFSET(Volume!L13,13-ROW(),ROW()-13)*10^9 -> 320000000 | M13: =OFFSET(Volume!M13,14-ROW(),ROW()-14)*10^9 -> 405000000 | O13: =OFFSET(Volume!O13,16-ROW(),ROW()-16)*10^9 -> 665500000 | V13: =OFFSET(Volume!V13,23-ROW(),ROW()-23)*10^9 -> 18000000
A14: Met. 12 | B14: =OFFSET(Volume!B14,3-ROW(),ROW()-3)*10^9 -> 384000000 | C14: =OFFSET(Volume!C14,4-ROW(),ROW()-4)*10^9 -> 2456500000 | D14: =OFFSET(Volume!D14,5-ROW(),ROW()-5)*10^9 -> 1912500000 | E14: =OFFSET(Volume!E14,6-ROW(),ROW()-6)*10^9 -> 2560000000 | F14: =OFFSET(Volume!F14,7-ROW(),ROW()-7)*10^9 -> 700000000 | H14: =OFFSET(Volume!H14,9-ROW(),ROW()-9)*10^9 -> 650000000 | J14: =OFFSET(Volume!J14,11-ROW(),ROW()-11)*10^9 -> 108000000 | L14: =OFFSET(Volume!L14,13-ROW(),ROW()-13)*10^9 -> 171500000 | M14: =OFFSET(Volume!M14,14-ROW(),ROW()-14)*10^9 -> 269500000 | O14: =OFFSET(Volume!O14,16-ROW(),ROW()-16)*10^9 -> 392000000 | V14: =OFFSET(Volume!V14,23-ROW(),ROW()-23)*10^9 -> 18000000
A15: Met. 13 | B15: =OFFSET(Volume!B15,3-ROW(),ROW()-3)*10^9 -> 320000000 | C15: =OFFSET(Volume!C15,4-ROW(),ROW()-4)*10^9 -> 1912500000 | D15: =OFFSET(Volume!D15,5-ROW(),ROW()-5)*10^9 -> 1470000000 | E15: =OFFSET(Volume!E15,6-ROW(),ROW()-6)*10^9 -> 2304000000 | F15: =OFFSET(Volume!F15,7-ROW(),ROW()-7)*10^9 -> 600000000 | H15: =OFFSET(Volume!H15,9-ROW(),ROW()-9)*10^9 -> 544000000 | J15: =OFFSET(Volume!J15,11-ROW(),ROW()-11)*10^9 -> 75000000 | L15: =OFFSET(Volume!L15,13-ROW(),ROW()-13)*10^9 -> 87500000 | M15: =OFFSET(Volume!M15,14-ROW(),ROW()-14)*10^9 -> 245000000 | O15: =OFFSET(Volume!O15,16-ROW(),ROW()-16)*10^9 -> 352000000 | V15: =OFFSET(Volume!V15,23-ROW(),ROW()-23)*10^9 -> 13500000
A16: Met. 14 | B16: =OFFSET(Volume!B16,3-ROW(),ROW()-3)*10^9 -> 220500000 | C16: =OFFSET(Volume!C16,4-ROW(),ROW()-4)*10^9 -> 1666000000 | D16: =OFFSET(Volume!D16,5-ROW(),ROW()-5)*10^9 -> 1028500000 | E16: =OFFSET(Volume!E16,6-ROW(),ROW()-6)*10^9 -> 2304000000 | F16: =OFFSET(Volume!F16,7-ROW(),ROW()-7)*10^9 -> 445500000 | H16: =OFFSET(Volume!H16,9-ROW(),ROW()-9)*10^9 -> 486000000 | J16: =OFFSET(Volume!J16,11-ROW(),ROW()-11)*10^9 -> 62500000 | L16: =OFFSET(Volume!L16,13-ROW(),ROW()-13)*10^9 -> 75000000 | M16: =OFFSET(Volume!M16,14-ROW(),ROW()-14)*10^9 -> 220500000 | V16: =OFFSET(Volume!V16,23-ROW(),ROW()-23)*10^9 -> 13500000
A17: Met. 15 | B17: =OFFSET(Volume!B17,3-ROW(),ROW()-3)*10^9 -> 220500000 | C17: =OFFSET(Volume!C17,4-ROW(),ROW()-4)*10^9 -> 1008000000 | D17: =OFFSET(Volume!D17,5-ROW(),ROW()-5)*10^9 -> 936000000 | E17: =OFFSET(Volume!E17,6-ROW(),ROW()-6)*10^9 -> 2.1375e+09 | F17: =OFFSET(Volume!F17,7-ROW(),ROW()-7)*10^9 -> 320000000 | H17: =OFFSET(Volume!H17,9-ROW(),ROW()-9)*10^9 -> 320000000 | J17: =OFFSET(Volume!J17,11-ROW(),ROW()-11)*10^9 -> 40000000 | M17: =OFFSET(Volume!M17,14-ROW(),ROW()-14)*10^9 -> 162000000 | V17: =OFFSET(Volume!V17,23-ROW(),ROW()-23)*10^9 -> 13500000
A18: Met. 16 | B18: =OFFSET(Volume!B18,3-ROW(),ROW()-3)*10^9 -> 220500000 | C18: =OFFSET(Volume!C18,4-ROW(),ROW()-4)*10^9 -> 288000000 | D18: =OFFSET(Volume!D18,5-ROW(),ROW()-5)*10^9 -> 786500000 | E18: =OFFSET(Volume!E18,6-ROW(),ROW()-6)*10^9 -> 2.058e+09 | F18: =OFFSET(Volume!F18,7-ROW(),ROW()-7)*10^9 -> 220500000 | H18: =OFFSET(Volume!H18,9-ROW(),ROW()-9)*10^9 -> 269500000 | J18: =OFFSET(Volume!J18,11-ROW(),ROW()-11)*10^9 -> 40000000 | M18: =OFFSET(Volume!M18,14-ROW(),ROW()-14)*10^9 -> 126000000 | V18: =OFFSET(Volume!V18,23-ROW(),ROW()-23)*10^9 -> 13500000
A19: Met. 17 | B19: =OFFSET(Volume!B19,3-ROW(),ROW()-3)*10^9 -> 196000000 | C19: =OFFSET(Volume!C19,4-ROW(),ROW()-4)*10^9 -> 269500000 | D19: =OFFSET(Volume!D19,5-ROW(),ROW()-5)*10^9 -> 786500000 | E19: =OFFSET(Volume!E19,6-ROW(),ROW()-6)*10^9 -> 1872000000 | F19: =OFFSET(Volume!F19,7-ROW(),ROW()-7)*10^9 -> 220500000 | H19: =OFFSET(Volume!H19,9-ROW(),ROW()-9)*10^9 -> 196000000 | J19: =OFFSET(Volume!J19,11-ROW(),ROW()-11)*10^9 -> 32000000 | M19: =OFFSET(Volume!M19,14-ROW(),ROW()-14)*10^9 -> 108000000 | V19: =OFFSET(Volume!V19,23-ROW(),ROW()-23)*10^9 -> 13500000
A20: Met. 18 | B20: =OFFSET(Volume!B20,3-ROW(),ROW()-3)*10^9 -> 62500000 | C20: =OFFSET(Volume!C20,4-ROW(),ROW()-4)*10^9 -> 171500000 | D20: =OFFSET(Volume!D20,5-ROW(),ROW()-5)*10^9 -> 786500000 | E20: =OFFSET(Volume!E20,6-ROW(),ROW()-6)*10^9 -> 1690000000 | F20: =OFFSET(Volume!F20,7-ROW(),ROW()-7)*10^9 -> 196000000 | H20: =OFFSET(Volume!H20,9-ROW(),ROW()-9)*10^9 -> 196000000 | J20: =OFFSET(Volume!J20,11-ROW(),ROW()-11)*10^9 -> 32000000 | M20: =OFFSET(Volume!M20,14-ROW(),ROW()-14)*10^9 -> 87500000 | V20: =OFFSET(Volume!V20,23-ROW(),ROW()-23)*10^9 -> 13500000
A21: Met. 19 | C21: =OFFSET(Volume!C21,4-ROW(),ROW()-4)*10^9 -> 126000000 | D21: =OFFSET(Volume!D21,5-ROW(),ROW()-5)*10^9 -> 700000000 | E21: =OFFSET(Volume!E21,6-ROW(),ROW()-6)*10^9 -> 1690000000 | F21: =OFFSET(Volume!F21,7-ROW(),ROW()-7)*10^9 -> 171500000 | H21: =OFFSET(Volume!H21,9-ROW(),ROW()-9)*10^9 -> 171500000 | J21: =OFFSET(Volume!J21,11-ROW(),ROW()-11)*10^9 -> 32000000 | M21: =OFFSET(Volume!M21,14-ROW(),ROW()-14)*10^9 -> 87500000 | V21: =OFFSET(Volume!V21,23-ROW(),ROW()-23)*10^9 -> 13500000
A22: Met. 20 | C22: =OFFSET(Volume!C22,4-ROW(),ROW()-4)*10^9 -> 126000000 | D22: =OFFSET(Volume!D22,5-ROW(),ROW()-5)*10^9 -> 550000000 | E22: =OFFSET(Volume!E22,6-ROW(),ROW()-6)*10^9 -> 1440000000 | F22: =OFFSET(Volume!F22,7-ROW(),ROW()-7)*10^9 -> 75000000 | H22: =OFFSET(Volume!H22,9-ROW(),ROW()-9)*10^9 -> 144000000 | J22: =OFFSET(Volume!J22,11-ROW(),ROW()-11)*10^9 -> 13500000 | M22: =OFFSET(Volume!M22,14-ROW(),ROW()-14)*10^9 -> 75000000 | V22: =OFFSET(Volume!V22,23-ROW(),ROW()-23)*10^9 -> 13500000
A23: Met. 21 | C23: =OFFSET(Volume!C23,4-ROW(),ROW()-4)*10^9 -> 75000000 | D23: =OFFSET(Volume!D23,5-ROW(),ROW()-5)*10^9 -> 5.265e+08 | E23: =OFFSET(Volume!E23,6-ROW(),ROW()-6)*10^9 -> 1296000000 | F23: =OFFSET(Volume!F23,7-ROW(),ROW()-7)*10^9 -> 75000000 | H23: =OFFSET(Volume!H23,9-ROW(),ROW()-9)*10^9 -> 144000000 | J23: =OFFSET(Volume!J23,11-ROW(),ROW()-11)*10^9 -> 13500000 | M23: =OFFSET(Volume!M23,14-ROW(),ROW()-14)*10^9 -> 62500000 | V23: =OFFSET(Volume!V23,23-ROW(),ROW()-23)*10^9 -> 6000000
A24: Met. 22 | C24: =OFFSET(Volume!C24,4-ROW(),ROW()-4)*10^9 -> 32000000 | D24: =OFFSET(Volume!D24,5-ROW(),ROW()-5)*10^9 -> 500000000 | E24: =OFFSET(Volume!E24,6-ROW(),ROW()-6)*10^9 -> 1224000000 | H24: =OFFSET(Volume!H24,9-ROW(),ROW()-9)*10^9 -> 144000000 | J24: =OFFSET(Volume!J24,11-ROW(),ROW()-11)*10^9 -> 13500000 | M24: =OFFSET(Volume!M24,14-ROW(),ROW()-14)*10^9 -> 62500000
A25: Met. 23 | C25: =OFFSET(Volume!C25,4-ROW(),ROW()-4)*10^9 -> 32000000 | D25: =OFFSET(Volume!D25,5-ROW(),ROW()-5)*10^9 -> 416000000 | E25: =OFFSET(Volume!E25,6-ROW(),ROW()-6)*10^9 -> 931500000 | H25: =OFFSET(Volume!H25,9-ROW(),ROW()-9)*10^9 -> 75000000 | J25: =OFFSET(Volume!J25,11-ROW(),ROW()-11)*10^9 -> 13500000 | M25: =OFFSET(Volume!M25,14-ROW(),ROW()-14)*10^9 -> 62500000
A26: Met. 24 | C26: =OFFSET(Volume!C26,4-ROW(),ROW()-4)*10^9 -> 32000000 | D26: =OFFSET(Volume!D26,5-ROW(),ROW()-5)*10^9 -> 405000000 | E26: =OFFSET(Volume!E26,6-ROW(),ROW()-6)*10^9 -> 726000000 | H26: =OFFSET(Volume!H26,9-ROW(),ROW()-9)*10^9 -> 40000000
A27: Met. 25 | C27: =OFFSET(Volume!C27,4-ROW(),ROW()-4)*10^9 -> 18000000 | D27: =OFFSET(Volume!D27,5-ROW(),ROW()-5)*10^9 -> 288000000 | E27: =OFFSET(Volume!E27,6-ROW(),ROW()-6)*10^9 -> 700000000 | H27: =OFFSET(Volume!H27,9-ROW(),ROW()-9)*10^9 -> 32000000
A28: Met. 26 | D28: =OFFSET(Volume!D28,5-ROW(),ROW()-5)*10^9 -> 288000000 | E28: =OFFSET(Volume!E28,6-ROW(),ROW()-6)*10^9 -> 352000000
A29: Met. 27 | E29: =OFFSET(Volume!E29,6-ROW(),ROW()-6)*10^9 -> 352000000
A30: Met. 28 | E30: =OFFSET(Volume!E30,6-ROW(),ROW()-6)*10^9 -> 288000000
A31: Met. 29 | E31: =OFFSET(Volume!E31,6-ROW(),ROW()-6)*10^9 -> 256000000
A32: Met. 30 | E32: =OFFSET(Volume!E32,6-ROW(),ROW()-6)*10^9 -> 196000000
A33: Tumor Burden | B33: =SUM(B3:B32) -> 255059500000 | C33: =SUM(C3:C32) -> 230942500000 | D33: =SUM(D3:D32) -> 173625000000 | E33: =SUM(E3:E32) -> 144490500000 | F33: =SUM(F3:F32) -> 104656000000 | G33: =SUM(G3:G32) -> 98073000000 | H33: =SUM(H3:H32) -> 90813000000 | I33: =SUM(I3:I32) -> 73611000000 | ... W33: =SUM(W3:W32) -> 847000000

Sheet Raw Data
A1: Patient: | B1: N1
A2: Date of scan: | B2: 41033 | C2: Tumor Size Screening (in cm) | E2: Location | F2: Volume | G2: Volume
A3: Description of Target Lesions | C3: long axis | D3: short axis | F3: (in cm³) | G3: (in cells)
A4: Pancreatic mass | C4: 8.6 | D4: 7.2 | E4: 13B:34 | F4: =C4*D4*D4/2 -> 222.912 | G4: =F4*10^9 -> 222912000000
A5: Mesenteric implant | C5: 2.8 | D5: 2.2 | E5: 0.27638889 | F5: =C5*D5*D5/2 -> 6.776 | G5: =F5*10^9 -> 6.776e+09
A6: Mesenteric nodule | C6: 1 | D6: 0.8 | E6: 0.27638889 | F6: =C6*D6*D6/2 -> 0.32 | G6: =F6*10^9 -> 3.2e+08
A7: Right omental nodule | C7: 0.9 | D7: 0.7 | E7: 0.28125 | F7: =C7*D7*D7/2 -> 0.2205 | G7: =F7*10^9 -> 2.205e+08
A8: Retrocecal mass | C8: 1.9 | D8: 1.4 | E8: 6; 63 | F8: =C8*D8*D8/2 -> 1.862 | G8: =F8*10^9 -> 1.862e+09
A9: Rt paracolic nodule | C9: 1.2 | D9: 0.8 | E9: 6; 45 | F9: =C9*D9*D9/2 -> 0.384 | G9: =F9*10^9 -> 384000000
A10: Liver metastasis left dome | C10: 1.7 | D10: 1.2 | E10: 6; 11 | F10: =C10*D10*D10/2 -> 1.224 | G10: =F10*10^9 -> 1224000000
A11: Liver metastasis posterior right | C11: 1.1 | D11: 1 | E11: 0.25902778 | F11: =C11*D11*D11/2 -> 0.55 | G11: =F11*10^9 -> 550000000
A12: Liver metastasis lateral right | C12: 0.5 | D12: 0.5 | E12: 6; 15 | F12: =C12*D12*D12/2 -> 0.0625 | G12: =F12*10^9 -> 62500000
A13: Liver metastasis left lobe | C13: 0.8 | D13: 0.7 | E13: 6; 18 | F13: =C13*D13*D13/2 -> 0.196 | G13: =F13*10^9 -> 1.96e+08
A14: Liver metastasis posterior right | C14: 0.9 | D14: 0.7 | E14: 6; 18 | F14: =C14*D14*D14/2 -> 0.2205 | G14: =F14*10^9 -> 2.205e+08
A15: Liver metastasis right lobe | C15: 0.9 | D15: 0.7 | E15: 6; 18 | F15: =C15*D15*D15/2 -> 0.2205 | G15: =F15*10^9 -> 2.205e+08
A16: Liver metastasis inferior right | C16: 1.5 | D16: 1 | E16: 6; 23 | F16: =C16*D16*D16/2 -> 0.75 | G16: =F16*10^9 -> 750000000
A17: Liver metastasis inferior right | C17: 1.2 | D17: 0.9 | E17: 6; 39 | F17: =C17*D17*D17/2 -> 0.486 | G17: =F17*10^9 -> 4.86e+08
A18: Pelvic cul de sac implant | C18: 3.3 | D18: 2.9 | E18: 13B; 64 | F18: =C18*D18*D18/2 -> 13.8765 | G18: =F18*10^9 -> 1.38765e+10
A19: Peripancreatic node | C19: 1 | D19: 0.9 | E19: 6; 21 | F19: =C19*D19*D19/2 -> 0.405 | G19: =F19*10^9 -> 405000000
A20: Periportal node | C20: 1.7 | D20: 0.8 | E20: 6; 20 | F20: =C20*D20*D20/2 -> 0.544 | G20: =F20*10^9 -> 544000000
A21: Mesenteric adenopathy | C21: 3.6 | D21: 1.5 | E21: 13B: 30 | F21: =C21*D21*D21/2 -> 4.05 | G21: =F21*10^9 -> 4.05e+09
A22: Total: | F22: =SUM(F4:F21) -> 255.0595 | G22: =F22*10^9 -> 2.550595e+11
A24: Patient: | B24: N2
A25: Date of scan: | B25: 40529 | C25: Tumor Size Screening (in cm) | E25: Location | F25: Volume | G25: Volume
A26: Description of Target Lesions | C26: long axis | D26: short axis | F26: (in cm³) | G26: (in cells)
A27: RUL lung nodule | C27: 0.7 | D27: 0.6 | E27: 6; 18 | F27: =C27*D27*D27/2 -> 0.126 | G27: =F27*10^9 -> 126000000
A28: RLL lung nodule | C28: 0.6 | D28: 0.5 | E28: 6; 26 | F28: =C28*D28*D28/2 -> 0.075 | G28: =F28*10^9 -> 75000000
A29: LUL lung nodule | C29: 0.4 | D29: 0.4 | E29: 6; 26 | F29: =C29*D29*D29/2 -> 0.032 | G29: =F29*10^9 -> 32000000
A30: RUL lung nodule | C30: 0.4 | D30: 0.4 | E30: 6;27 | F30: =C30*D30*D30/2 -> 0.032 | G30: =F30*10^9 -> 32000000
A31: RUL lung nodule | C31: 0.4 | D31: 0.4 | E31: 6;29 | F31: =C31*D31*D31/2 -> 0.032 | G31: =F31*10^9 -> 32000000
A32: LLL lung nodule | C32: 0.9 | D32: 0.8 | E32: 6; 34 | F32: =C32*D32*D32/2 -> 0.288 | G32: =F32*10^9 -> 2.88e+08
A33: LLL lung nodule | C33: 0.7 | D33: 0.6 | E33: 6; 47 | F33: =C33*D33*D33/2 -> 0.126 | G33: =F33*10^9 -> 126000000
A34: LLL lung nodule | C34: 0.4 | D34: 0.3 | E34: 6; 44 | F34: =C34*D34*D34/2 -> 0.018 | G34: =F34*10^9 -> 18000000
A35: Liver lesion anterior dome | C35: 0.7 | D35: 0.7 | E35: 5; 68 | F35: =C35*D35*D35/2 -> 0.1715 | G35: =F35*10^9 -> 1.715e+08
A36: Liver lesion S II | C36: 1.7 | D36: 1.4 | E36: 5; 69 | F36: =C36*D36*D36/2 -> 1.666 | G36: =F36*10^9 -> 1666000000
A37: Liver lesion posterior left | C37: 2.7 | D37: 2.2 | E37: 5;72 | F37: =C37*D37*D37/2 -> 6.534 | G37: =F37*10^9 -> 6.534e+09
A38: Liver lesion posterior right | C38: 3.1 | D38: 2.2 | E38: 5; 74 | F38: =C38*D38*D38/2 -> 7.502 | G38: =F38*10^9 -> 7.502e+09
... A51: Liver lesion inferior right | C51: 3.4 | D51: 2.4 | E51: 5;132 | F51: =C51*D51*D51/2 -> 9.792 | G51: =F51*10^9 -> 9792000000
A52: Total: | F52: =SUM(F27:F51) -> 230.9425 | G52: =F52*10^9 -> 2.309425e+11
A54: Patient: | B54: N3
...

Sheet Volume
A1: Patient | B1: Volume in cm³
A2: ID | B2: Met. 1 | C2: Met. 2 | D2: Met. 3 | E2: Met. 4 | F2: Met. 5 | G2: Met. 6 | H2: Met. 7 | I2: Met. 8 | J2: Met. 9 | K2: Met. 10 | L2: Met. 11 | M2: Met. 12 | N2: Met. 13 | O2: Met. 14 | P2: Met. 15 | Q2: Met. 16 | R2: Met. 17 | S2: Met. 18 | T2: Met. 19 | U2: Met. 20 | V2: Met. 21 | W2: Met. 22 | X2: Met. 23 | Y2: Met. 24 | Z2: Met. 25 | AA2: Met. 26 | AB2: Met. 27 | AC2: Met. 28 | AD2: Met. 29 | AE2: Met. 30
A3: N1 | B3: 222.912 | C3: 13.8765 | D3: 6.776 | E3: 4.05 | F3: 1.862 | G3: 1.224 | H3: 0.75 | I3: 0.55 | J3: 0.544 | K3: 0.486 | L3: 0.405 | M3: 0.384 | N3: 0.32 | O3: 0.2205 | P3: 0.2205 | Q3: 0.2205 | R3: 0.196 | S3: 0.0625
A4: N2 | B4: 137.4995 | C4: 22.869 | D4: 11.76 | E4: 9.792 | F4: 9.6875 | G4: 7.502 | H4: 6.877 | I4: 6.534 | J4: 3.61 | K4: 3.564 | L4: 3.0345 | M4: 2.4565 | N4: 1.9125 | O4: 1.666 | P4: 1.008 | Q4: 0.288 | R4: 0.2695 | S4: 0.1715 | T4: 0.126 | U4: 0.126 | V4: 0.075 | W4: 0.032 | X4: 0.032 | Y4: 0.032 | Z4: 0.018
A5: N3 | B5: 46.2275 | C5: 30.8025 | D5: 20.48 | E5: 18 | F5: 17.661 | G5: 9.802 | H5: 7.1415 | I5: 3.712 | J5: 3.072 | K5: 2.89 | L5: 2.4565 | M5: 1.9125 | N5: 1.47 | O5: 1.0285 | P5: 0.936 | Q5: 0.7865 | R5: 0.7865 | S5: 0.7865 | T5: 0.7 | U5: 0.55 | V5: 0.5265 | W5: 0.5 | X5: 0.416 | Y5: 0.405 | Z5: 0.288 | AA5: 0.288
A6: N4 | B6: 49.818 | C6: 24.276 | D6: 12.152 | E6: 9.922 | F6: 4.86 | G6: 3.9015 | H6: 3.564 | I6: 2.944 | J6: 2.944 | K6: 2.916 | L6: 2.816 | M6: 2.56 | N6: 2.304 | O6: 2.304 | P6: 2.1375 | Q6: 2.058 | R6: 1.872 | S6: 1.69 | T6: 1.69 | U6: 1.44 | V6: 1.296 | W6: 1.224 | X6: 0.9315 | Y6: 0.726 | Z6: 0.7 | AA6: 0.352 | AB6: 0.352 | AC6: 0.288 | AD6: 0.256 | AE6: 0.196
A7: N5 | B7: 46.746 | C7: 19.208 | D7: 12.615 | E7: 5.324 | F7: 4.8 | G7: 4.212 | H7: 3.0345 | I7: 2.688 | J7: 1.2675 | K7: 1.008 | L7: 0.729 | M7: 0.7 | N7: 0.6 | O7: 0.4455 | P7: 0.32 | Q7: 0.2205 | R7: 0.2205 | S7: 0.196 | T7: 0.1715 | U7: 0.075 | V7: 0.075
A8: N6 | B8: 77.2475 | C8: 8.064 | D8: 6.2 | E8: 2.7455 | F8: 1.8 | G8: 1.372 | H8: 0.5 | I8: 0.144
A9: N7 | B9: 24.5 | C9: 22.3245 | D9: 19.8 | E9: 8.954 | F9: 3.072 | G9: 2.925 | H9: 1.666 | I9: 1.352 | J9: 1.1495 | K9: 1.008 | L9: 0.65 | M9: 0.65 | N9: 0.544 | O9: 0.486 | P9: 0.32 | Q9: 0.2695 | R9: 0.196 | S9: 0.196 | T9: 0.1715 | U9: 0.144 | V9: 0.144 | W9: 0.144 | X9: 0.075 | Y9: 0.04 | Z9: 0.032
A10: N8 | B10: 48.9985 | C10: 10.816 | D10: 5.733 | E10: 3.7905 | F10: 2.304 | G10: 1.2675 | H10: 0.4455 | I10: 0.256
A11: N9 | B11: 47.5875 | C11: 12.936 | D11: 0.936 | E11: 0.55 | F11: 0.448 | G11: 0.196 | H11: 0.18 | I11: 0.1715 | J11: 0.126 | K11: 0.126 | L11: 0.108 | M11: 0.108 | N11: 0.075 | O11: 0.0625 | P11: 0.04 | Q11: 0.04 | R11: 0.032 | S11: 0.032 | T11: 0.032 | U11: 0.0135 | V11: 0.0135 | W11: 0.0135 | X11: 0.0135
A12: N10 | B12: 26.568 | C12: 16.072 | D12: 9.0405 | E12: 2.475 | F12: 1
A13: N11 | B13: 36.822 | C13: 4.698 | D13: 2.4565 | E13: 2.025 | F13: 1.9125 | G13: 1.6875 | H13: 1.2675 | I13: 1.08 | J13: 0.75 | K13: 0.352 | L13: 0.32 | M13: 0.1715 | N13: 0.0875 | O13: 0.075
A14: N12 | B14: 20.992 | C14: 8.125 | D14: 7.6705 | E14: 2.89 | F14: 2.176 | G14: 1.47 | H14: 1.44 | I14: 0.6075 | J14: 0.55 | K14: 0.55 | L14: 0.405 | M14: 0.2695 | N14: 0.245 | O14: 0.2205 | P14: 0.162 | Q14: 0.126 | R14: 0.108 | S14: 0.0875 | T14: 0.0875 | U14: 0.075 | V14: 0.0625 | W14: 0.0625 | X14: 0.0625
A15: N13 | B15: 10.478 | C15: 8.064 | D15: 6.615 | E15: 5.0715 | F15: 3.584 | G15: 3.328 | H15: 2.688 | I15: 0.936 | J15: 0.288
A16: N14 | B16: 26.4915 | C16: 2.842 | D16: 1.7745 | E16: 1.372 | F16: 1.331 | G16: 1.2 | H16: 1.183 | I16: 1.0985 | J16: 1.0985 | K16: 0.729 | L16: 0.6655 | M16: 0.392 | N16: 0.352
A17: N15 | B17: 25.047 | C17: 2.16 | D17: 1.5125 | E17: 1.512 | F17: 1.2705 | G17: 1.152 | H17: 0.7865 | I17: 0.648
A18: N16 | B18: 17.1 | C18: 2.7455 | D18: 1.224 | E18: 0.384 | F18: 0.256 | G18: 0.144 | H18: 0.0875
A19: N17 | B19: 10.5705 | C19: 2.601 | D19: 1.47 | E19: 1.2675 | F19: 1.183 | G19: 1.08 | H19: 1.008 | I19: 0.847 | J19: 0.4455 | K19: 0.352
A20: N18 | B20: 18.954 | C20: 0.55 | D20: 0.32 | E20: 0.256
A21: N19 | B21: 15.979 | C21: 0.847 | D21: 0.245 | E21: 0.198 | F21: 0.18 | G21: 0.144 | H21: 0.144 | I21: 0.126 | J21: 0.048
A22: N20 | B22: 1.008 | C22: 0.3645 | D22: 0.2205
A23: N21 | B23: 0.7865 | C23: 0.075 | D23: 0.075 | E23: 0.04 | F23: 0.04 | G23: 0.04 | H23: 0.032 | I23: 0.032 | J23: 0.032 | K23: 0.018 | L23: 0.018 | M23: 0.018 | N23: 0.0135 | O23: 0.0135 | P23: 0.0135 | Q23: 0.0135 | R23: 0.0135 | S23: 0.0135 | T23: 0.0135 | U23: 0.0135 | V23: 0.006
A24: N22 | B24: 0.847
